2025-04-03 02:24:45,182 INFO: Training configuration saved to runs/esm2_650m_ecoli_finetuning_2/train_config.yaml
Traceback (most recent call last):
  File "/home/sdowell/miniconda3/envs/thesis/lib/python3.13/site-packages/huggingface_hub/utils/_http.py", line 409, in hf_raise_for_status
    response.raise_for_status()
    ~~~~~~~~~~~~~~~~~~~~~~~~~^^
  File "/home/sdowell/miniconda3/envs/thesis/lib/python3.13/site-packages/requests/models.py", line 1024, in raise_for_status
    raise HTTPError(http_error_msg, response=self)
requests.exceptions.HTTPError: 404 Client Error: Not Found for url: https://huggingface.co/hugohrban/esm2_t33_650M/resolve/main/config.json

The above exception was the direct cause of the following exception:

Traceback (most recent call last):
  File "/home/sdowell/miniconda3/envs/thesis/lib/python3.13/site-packages/transformers/utils/hub.py", line 342, in cached_file
    resolved_file = hf_hub_download(
        path_or_repo_id,
    ...<10 lines>...
        local_files_only=local_files_only,
    )
  File "/home/sdowell/miniconda3/envs/thesis/lib/python3.13/site-packages/huggingface_hub/utils/_validators.py", line 114, in _inner_fn
    return fn(*args, **kwargs)
  File "/home/sdowell/miniconda3/envs/thesis/lib/python3.13/site-packages/huggingface_hub/file_download.py", line 862, in hf_hub_download
    return _hf_hub_download_to_cache_dir(
        # Destination
    ...<14 lines>...
        force_download=force_download,
    )
  File "/home/sdowell/miniconda3/envs/thesis/lib/python3.13/site-packages/huggingface_hub/file_download.py", line 969, in _hf_hub_download_to_cache_dir
    _raise_on_head_call_error(head_call_error, force_download, local_files_only)
    ~~~~~~~~~~~~~~~~~~~~~~~~~^^^^^^^^^^^^^^^^^^^^^^^^^^^^^^^^^^^^^^^^^^^^^^^^^^^
  File "/home/sdowell/miniconda3/envs/thesis/lib/python3.13/site-packages/huggingface_hub/file_download.py", line 1486, in _raise_on_head_call_error
    raise head_call_error
  File "/home/sdowell/miniconda3/envs/thesis/lib/python3.13/site-packages/huggingface_hub/file_download.py", line 1376, in _get_metadata_or_catch_error
    metadata = get_hf_file_metadata(
        url=url, proxies=proxies, timeout=etag_timeout, headers=headers, token=token
    )
  File "/home/sdowell/miniconda3/envs/thesis/lib/python3.13/site-packages/huggingface_hub/utils/_validators.py", line 114, in _inner_fn
    return fn(*args, **kwargs)
  File "/home/sdowell/miniconda3/envs/thesis/lib/python3.13/site-packages/huggingface_hub/file_download.py", line 1296, in get_hf_file_metadata
    r = _request_wrapper(
        method="HEAD",
    ...<5 lines>...
        timeout=timeout,
    )
  File "/home/sdowell/miniconda3/envs/thesis/lib/python3.13/site-packages/huggingface_hub/file_download.py", line 280, in _request_wrapper
    response = _request_wrapper(
        method=method,
    ...<2 lines>...
        **params,
    )
  File "/home/sdowell/miniconda3/envs/thesis/lib/python3.13/site-packages/huggingface_hub/file_download.py", line 304, in _request_wrapper
    hf_raise_for_status(response)
    ~~~~~~~~~~~~~~~~~~~^^^^^^^^^^
  File "/home/sdowell/miniconda3/envs/thesis/lib/python3.13/site-packages/huggingface_hub/utils/_http.py", line 458, in hf_raise_for_status
    raise _format(RepositoryNotFoundError, message, response) from e
huggingface_hub.errors.RepositoryNotFoundError: 404 Client Error. (Request ID: Root=1-67edf16d-1439ce762b8f0cfd0101533b;a03e9ee1-83b1-4b7f-96b3-23d3c5bae095)

Repository Not Found for url: https://huggingface.co/hugohrban/esm2_t33_650M/resolve/main/config.json.
Please make sure you specified the correct `repo_id` and `repo_type`.
If you are trying to access a private or gated repo, make sure you are authenticated.

The above exception was the direct cause of the following exception:

Traceback (most recent call last):
  File "/home/sdowell/scratch/Thesis/BenchmarkingFinetuning/finetuneESM2_ProGen2_LoRA.py", line 613, in <module>
    main()
    ~~~~^^
  File "/home/sdowell/scratch/Thesis/BenchmarkingFinetuning/finetuneESM2_ProGen2_LoRA.py", line 392, in main
    model = EsmForMaskedLM.from_pretrained(config.base_model)
  File "/home/sdowell/miniconda3/envs/thesis/lib/python3.13/site-packages/transformers/modeling_utils.py", line 262, in _wrapper
    return func(*args, **kwargs)
  File "/home/sdowell/miniconda3/envs/thesis/lib/python3.13/site-packages/transformers/modeling_utils.py", line 3540, in from_pretrained
    resolved_config_file = cached_file(
        pretrained_model_name_or_path,
    ...<11 lines>...
        _raise_exceptions_for_connection_errors=False,
    )
  File "/home/sdowell/miniconda3/envs/thesis/lib/python3.13/site-packages/transformers/utils/hub.py", line 365, in cached_file
    raise EnvironmentError(
    ...<4 lines>...
    ) from e
OSError: hugohrban/esm2_t33_650M is not a local folder and is not a valid model identifier listed on 'https://huggingface.co/models'
If this is a private repository, make sure to pass a token having permission to this repo either by logging in with `huggingface-cli login` or by passing `token=<your_token>`
